Workbook

Sheet FORM
A1: PAGE 1
A2: client name | C2: ='PAGE 1'!B1 -> KHOR MEOW SWEE
A3: coordinate | C3: =('PAGE 1'!B2)&('PAGE 1'!C2) -> 5.182659100.480854
A4: short address | C4: ='PAGE 1'!B3 -> 19, LORONG CENDERAWASIH INDAH 4
A5: PAGE 2
A6: Orientation #1 | C6: Orientation #2 | E6: Orientation #3 | G6: Orientation #4
A7: Titl/Azimut | B7: =PAGE2!B9 -> 20/180° | C7: Titl/Azimut | D7: =PAGE2!D9 -> 20/180° | E7: Titl/Azimut | F7: =PAGE2!F9 -> 20/180° | G7: Titl/Azimut | H7: =PAGE2!I9 -> 20/180°
A8: Pv Array | C8: Inverters | E8: Battery pack
A9: no of modules | B9: =SUM(GlobHor_DiffHor!D3:D6) -> 28 | C9: Nb. Of units | D9: 1 | E9: nb. Of units | F9: 1
A10: pnom total | B10: =GlobHor_DiffHor!H3 -> 6.93 | C10: total power | D10: =5 -> 5 | E10: voltage | F10: =51 -> 51
C11: pnomr ratio | D11: =B10/D10 -> 1.386 | E11: capacity | F11: =F9*314 -> 314
A12: Results summary
A13: Produced energy | B13: =GlobHor_DiffHor!O23 -> 8662.4212
A14: user energy | B14: =GlobHor_DiffHor!Q23 -> 9600
A15: specific production | B15: =B13/B10 -> 1249.9886
A16: Perf Ratio PR | B16: =GlobHor_DiffHor!T23*100 -> 81.451613
A17: Solar fraction SF | B17: =GlobHor_DiffHor!R23/GlobHor_DiffHor!Q23*100 -> 89.151412
A18: PAGE 3
A19: Storage | B19: Self consumption
A20: Jan | B20: =GlobHor_DiffHor!Q11 -> 768 | D20: =GlobHor_DiffHor!Q16 -> 912 | F20: =GlobHor_DiffHor!Q22 -> 816
A21: Feb | B21: =GlobHor_DiffHor!Q12 -> 720 | D21: =GlobHor_DiffHor!Q17 -> 864 | F21: =GlobHor_DiffHor!Q22 -> 816
A22: March | B22: =GlobHor_DiffHor!Q13 -> 768 | D22: =GlobHor_DiffHor!Q18 -> 816 | F22: =GlobHor_DiffHor!Q23 -> 9600
A23: April | B23: =GlobHor_DiffHor!Q14 -> 816 | D23: =GlobHor_DiffHor!Q19 -> 768
A24: May | B24: =GlobHor_DiffHor!Q15 -> 864 | D24: =GlobHor_DiffHor!Q20 -> 768
A25: PV Array Characteristics
A26: Manufacturer | C26: ='PAGE 3'!B14 -> Astronergy | D26: Manufacturer | G26: ='PAGE 3'!D14 -> Hoymiles
A27: Model | C27: ='PAGE 3'!B15 -> CHSMM66RN(DG)/F-BH-630 | D27: Model | G27: ='PAGE 3'!D15 -> HIS-5L-G3
A28: (Custom parameters definition) | C28: ='PAGE 3'!B16 -> CHSMM66RN(DG)/F-BH-630.PAN | D28: (Custom parameters definition)
A29: Unit Nom. Power | C29: ='PAGE 3'!B17 -> 630 | D29: Unit Nom. Power | G29: ='PAGE 3'!D17 -> 5
A30: Array #1 - PV Array
A31: Orientation | B31: ='PAGE 3'!B20 -> 1 | C31: Number of inverters | D31: =ROUND(B34/(B10*1000)*100,0) -> 64 | E31: =D31/100 -> 0.64
A32: Tilt/Azimuth | B32: ='PAGE 3'!B21 -> 20/180° | C32: Total power | D32: ='PAGE 3'!D23 -> 3.2
A33: Number of PV modules | B33: ='PAGE 3'!B22 -> 7
A34: Nominal (STC) | B34: ='PAGE 3'!B23 -> 4410 | C34: Operating voltage | D34: ='PAGE 3'!D25 -> 90-550
A35: Modules | B35: ='PAGE 3'!B24 -> 7
A36: At operating cond. (50°C) | C36: Pnom ratio | D36: ='PAGE 3'!D26 -> 1.386
A37: Pmpp | B37: ='PAGE 3'!B26 -> 4116
A38: U mpp | B38: ='PAGE 3'!B27 -> 263.9
A39: I mpp | B39: ='PAGE 3'!B28 -> 15.596817
A40: Array #2 - PV Array
...

Sheet GlobHor_DiffHor
N1: INPUT | O1: Value | P1: Unit
C2: Orientation | D2: No. Panel | E2: TF | G2: INPUT | H2: Value | I2: Unit | N2: P50 Annual Production | O2: =O23 -> 8662.4212 | P2: kWh/year
C3: Ori 1 | D3: ='PAGE 3'!B22 -> 7 | E3: 0.97 | G3: PV Size | H3: =PAGE2!B14 -> 6.93 | I3: kWp | N3: Year-to-Year Weather Variability | O3: ='PAGE 7'!B2/100 -> 0.038 | P3: % | R3: Soiling & Mismatch Uncertainty | U3: 0.01 | V3: %
C4: Ori 2 | D4: ='PAGE 3'!B32 -> 7 | E4: 0.95 | N4: PV Module Uncertainty | O4: 0.01 | P4: % | R4: Degradation Uncertainty | U4: 0.01 | V4: %
C5: Ori 3 | D5: ='PAGE 3'!B42 -> 7 | E5: 0.97 | G5: Optical Loss | H5: 0.05 | I5: % | N5: Inverter Efficiency Uncertainty | O5: 0.005 | P5: % | R5: Customer Variability | U5: =O3 -> 0.038 | V5: %
C6: Ori 4 | D6: ='PAGE 3'!B52 -> 7 | E6: 0.97 | G6: Annual Load | H6: ='PAGE 1'!B6 -> 9600 | I6: kWh/year | N6: Soiling & Mismatch Uncertainty | O6: 0.01 | P6: %
N7: Degradation Uncertainty | O7: 0.01 | P7: %
N8: Customer Variability | O8: =O3 -> 0.038 | P8: %
A9: Input / Month | B9: GlobHor | C9: Monthly % | D9: GlobHor | E9: Diffuse Ratio | F9: DiffHor | G9: T_Amb (°C) | H9: Ori1 GlobInc | I9: Ori2 GlobInc | J9: Ori3 GlobInc | K9: Ori4 GlobInc | L9: GlobInc | M9: GlobEff | N9: Monthly Performance Factor | O9: EArray | P9: Split % | Q9: E_User | R9: E_Solar | S9: E_Grid | T9: PR Ratio | U9: EFrGrid
A10: YEAR INPUT | B10: ='PAGE 1'!B5 -> 1800
A11: Jan | C11: 0.08 | D11: =$B$10*C11 -> 144 | E11: 0.55 | F11: =D11*E11 -> 79.2 | G11: 27.5 | H11: =D11*$E$3 -> 139.68 | I11: =D11*$E$4 -> 136.8 | J11: =D11*$E$5 -> 139.68 | K11: =D11*$E$6 -> 139.68 | L11: =((H11*$D$3)+(I11*$D$4)+(J11*$D$5)+(K11*$D$6))/SUM($D$3:$D$6) -> 138.96 | M11: =L11*(1-$H$5) -> 132.012 | N11: 0.82 | O11: =M11*$H$3*$N$11 -> 750.17139 | P11: 0.08 | Q11: =$H$6*P11 -> 768 | R11: =MIN(O11,Q11) -> 750.17139 | S11: =MAX(O11-R11,0) -> 0 | T11: =O11/(M11*$H$3) -> 0.82 | U11: =MAX(Q11-R11,0) -> 17.828609
A12: Feb | C12: 0.07 | D12: =$B$10*C12 -> 126 | E12: 0.52 | F12: =D12*E12 -> 65.52 | G12: 27.8 | H12: =D12*$E$3 -> 122.22 | I12: =D12*$E$4 -> 119.7 | J12: =D12*$E$5 -> 122.22 | K12: =D12*$E$6 -> 122.22 | L12: =((H12*$D$3)+(I12*$D$4)+(J12*$D$5)+(K12*$D$6))/SUM($D$3:$D$6) -> 121.59 | M12: =L12*(1-$H$5) -> 115.5105 | N12: 0.81 | O12: =M12*$H$3*$N$12 -> 648.39509 | P12: 0.075 | Q12: =$H$6*P12 -> 720 | R12: =MIN(O12,Q12) -> 648.39509 | S12: =MAX(O12-R12,0) -> 0 | T12: =O12/(M12*$H$3) -> 0.81 | U12: =MAX(Q12-R12,0) -> 71.60491
A13: Mar | C13: 0.06 | D13: =$B$10*C13 -> 108 | E13: 0.48 | F13: =D13*E13 -> 51.84 | G13: 28.2 | H13: =D13*$E$3 -> 104.76 | I13: =D13*$E$4 -> 102.6 | J13: =D13*$E$5 -> 104.76 | K13: =D13*$E$6 -> 104.76 | L13: =((H13*$D$3)+(I13*$D$4)+(J13*$D$5)+(K13*$D$6))/SUM($D$3:$D$6) -> 104.22 | M13: =L13*(1-$H$5) -> 99.009 | N13: 0.78 | O13: =M13*$H$3*$N$13 -> 535.18325 | P13: 0.08 | Q13: =$H$6*P13 -> 768 | R13: =MIN(O13,Q13) -> 535.18325 | S13: =MAX(O13-R13,0) -> 0 | T13: =O13/(M13*$H$3) -> 0.78 | U13: =MAX(Q13-R13,0) -> 232.81675
A14: Apr | C14: 0.09 | D14: =$B$10*C14 -> 162 | E14: 0.5 | F14: =D14*E14 -> 81 | G14: 28.5 | H14: =D14*$E$3 -> 157.14 | I14: =D14*$E$4 -> 153.9 | J14: =D14*$E$5 -> 157.14 | K14: =D14*$E$6 -> 157.14 | L14: =((H14*$D$3)+(I14*$D$4)+(J14*$D$5)+(K14*$D$6))/SUM($D$3:$D$6) -> 156.33 | M14: =L14*(1-$H$5) -> 148.5135 | N14: 0.82 | O14: =M14*$H$3*$N$14 -> 843.94282 | P14: 0.085 | Q14: =$H$6*P14 -> 816 | R14: =MIN(O14,Q14) -> 816 | S14: =MAX(O14-R14,0) -> 27.942815 | T14: =O14/(M14*$H$3) -> 0.82 | U14: =MAX(Q14-R14,0) -> 0
A15: May | C15: 0.08 | D15: =$B$10*C15 -> 144 | E15: 0.53 | F15: =D15*E15 -> 76.32 | G15: 28.8 | H15: =D15*$E$3 -> 139.68 | I15: =D15*$E$4 -> 136.8 | J15: =D15*$E$5 -> 139.68 | K15: =D15*$E$6 -> 139.68 | L15: =((H15*$D$3)+(I15*$D$4)+(J15*$D$5)+(K15*$D$6))/SUM($D$3:$D$6) -> 138.96 | M15: =L15*(1-$H$5) -> 132.012 | N15: 0.83 | O15: =M15*$H$3*$N$15 -> 759.31982 | P15: 0.09 | Q15: =$H$6*P15 -> 864 | R15: =MIN(O15,Q15) -> 759.31982 | S15: =MAX(O15-R15,0) -> 0 | T15: =O15/(M15*$H$3) -> 0.83 | U15: =MAX(Q15-R15,0) -> 104.68018
A16: Jun | C16: 0.09 | D16: =$B$10*C16 -> 162 | E16: 0.49 | F16: =D16*E16 -> 79.38 | G16: 28.9 | H16: =D16*$E$3 -> 157.14 | I16: =D16*$E$4 -> 153.9 | J16: =D16*$E$5 -> 157.14 | K16: =D16*$E$6 -> 157.14 | L16: =((H16*$D$3)+(I16*$D$4)+(J16*$D$5)+(K16*$D$6))/SUM($D$3:$D$6) -> 156.33 | M16: =L16*(1-$H$5) -> 148.5135 | N16: 0.82 | O16: =M16*$H$3*$N$16 -> 843.94282 | P16: 0.095 | Q16: =$H$6*P16 -> 912 | R16: =MIN(O16,Q16) -> 843.94282 | S16: =MAX(O16-R16,0) -> 0 | T16: =O16/(M16*$H$3) -> 0.82 | U16: =MAX(Q16-R16,0) -> 68.057185
A17: Jul | C17: 0.08 | D17: =$B$10*C17 -> 144 | E17: 0.45 | F17: =D17*E17 -> 64.8 | G17: 28.7 | H17: =D17*$E$3 -> 139.68 | I17: =D17*$E$4 -> 136.8 | J17: =D17*$E$5 -> 139.68 | K17: =D17*$E$6 -> 139.68 | L17: =((H17*$D$3)+(I17*$D$4)+(J17*$D$5)+(K17*$D$6))/SUM($D$3:$D$6) -> 138.96 | M17: =L17*(1-$H$5) -> 132.012 | N17: 0.81 | O17: =M17*$H$3*$N$17 -> 741.02296 | P17: 0.09 | Q17: =$H$6*P17 -> 864 | R17: =MIN(O17,Q17) -> 741.02296 | S17: =MAX(O17-R17,0) -> 0 | T17: =O17/(M17*$H$3) -> 0.81 | U17: =MAX(Q17-R17,0) -> 122.97704
A18: Aug | C18: 0.08 | D18: =$B$10*C18 -> 144 | E18: 0.46 | F18: =D18*E18 -> 66.24 | G18: 28.6 | H18: =D18*$E$3 -> 139.68 | I18: =D18*$E$4 -> 136.8 | J18: =D18*$E$5 -> 139.68 | K18: =D18*$E$6 -> 139.68 | L18: =((H18*$D$3)+(I18*$D$4)+(J18*$D$5)+(K18*$D$6))/SUM($D$3:$D$6) -> 138.96 | M18: =L18*(1-$H$5) -> 132.012 | N18: 0.79 | O18: =M18*$H$3*$N$18 -> 722.7261 | P18: 0.085 | Q18: =$H$6*P18 -> 816 | R18: =MIN(O18,Q18) -> 722.7261 | S18: =MAX(O18-R18,0) -> 0 | T18: =O18/(M18*$H$3) -> 0.79 | U18: =MAX(Q18-R18,0) -> 93.273904
A19: Sep | C19: 0.09 | D19: =$B$10*C19 -> 162 | E19: 0.5 | F19: =D19*E19 -> 81 | G19: 28.3 | H19: =D19*$E$3 -> 157.14 | I19: =D19*$E$4 -> 153.9 | J19: =D19*$E$5 -> 157.14 | K19: =D19*$E$6 -> 157.14 | L19: =((H19*$D$3)+(I19*$D$4)+(J19*$D$5)+(K19*$D$6))/SUM($D$3:$D$6) -> 156.33 | M19: =L19*(1-$H$5) -> 148.5135 | N19: 0.82 | O19: =M19*$H$3*$N$19 -> 843.94282 | P19: 0.08 | Q19: =$H$6*P19 -> 768 | R19: =MIN(O19,Q19) -> 768 | S19: =MAX(O19-R19,0) -> 75.942815 | T19: =O19/(M19*$H$3) -> 0.82 | U19: =MAX(Q19-R19,0) -> 0
A20: Oct | C20: 0.08 | D20: =$B$10*C20 -> 144 | E20: 0.55 | F20: =D20*E20 -> 79.2 | G20: 28 | H20: =D20*$E$3 -> 139.68 | I20: =D20*$E$4 -> 136.8 | J20: =D20*$E$5 -> 139.68 | K20: =D20*$E$6 -> 139.68 | L20: =((H20*$D$3)+(I20*$D$4)+(J20*$D$5)+(K20*$D$6))/SUM($D$3:$D$6) -> 138.96 | M20: =L20*(1-$H$5) -> 132.012 | N20: 0.83 | O20: =M20*$H$3*$N$20 -> 759.31982 | P20: 0.08 | Q20: =$H$6*P20 -> 768 | R20: =MIN(O20,Q20) -> 759.31982 | S20: =MAX(O20-R20,0) -> 0 | T20: =O20/(M20*$H$3) -> 0.83 | U20: =MAX(Q20-R20,0) -> 8.6801772
A21: Nov | C21: 0.06 | D21: =$B$10*C21 -> 108 | E21: 0.62 | F21: =D21*E21 -> 66.96 | G21: 27.7 | H21: =D21*$E$3 -> 104.76 | I21: =D21*$E$4 -> 102.6 | J21: =D21*$E$5 -> 104.76 | K21: =D21*$E$6 -> 104.76 | L21: =((H21*$D$3)+(I21*$D$4)+(J21*$D$5)+(K21*$D$6))/SUM($D$3:$D$6) -> 104.22 | M21: =L21*(1-$H$5) -> 99.009 | N21: 0.79 | O21: =M21*$H$3*$N$21 -> 542.04457 | P21: 0.075 | Q21: =$H$6*P21 -> 720 | R21: =MIN(O21,Q21) -> 542.04457 | S21: =MAX(O21-R21,0) -> 0 | T21: =O21/(M21*$H$3) -> 0.79 | U21: =MAX(Q21-R21,0) -> 177.95543
A22: Dec | C22: 0.07 | D22: =$B$10*C22 -> 126 | E22: 0.6 | F22: =D22*E22 -> 75.6 | G22: 27.5 | H22: =D22*$E$3 -> 122.22 | I22: =D22*$E$4 -> 119.7 | J22: =D22*$E$5 -> 122.22 | K22: =D22*$E$6 -> 122.22 | L22: =((H22*$D$3)+(I22*$D$4)+(J22*$D$5)+(K22*$D$6))/SUM($D$3:$D$6) -> 121.59 | M22: =L22*(1-$H$5) -> 115.5105 | N22: 0.84 | O22: =M22*$H$3*$N$22 -> 672.40972 | P22: 0.085 | Q22: =$H$6*P22 -> 816 | R22: =MIN(O22,Q22) -> 672.40972 | S22: =MAX(O22-R22,0) -> 0 | T22: =O22/(M22*$H$3) -> 0.84 | U22: =MAX(Q22-R22,0) -> 143.59028
A23: YEAR TOTAL | D23: =SUM(D11:D22) -> 1674 | F23: =SUM(F11:F22) -> 867.06 | G23: =AVERAGE(G11:G22) -> 28.208333 | H23: =D23*$E$3 -> 1623.78 | I23: =D23*$E$4 -> 1590.3 | J23: =D23*$E$5 -> 1623.78 | K23: =D23*$E$6 -> 1623.78 | L23: =((H23*$D$3)+(I23*$D$4)+(J23*$D$5)+(K23*$D$6))/SUM($D$3:$D$6) -> 1615.41 | M23: =SUM(M11:M22) -> 1534.6395 | O23: =SUM(O11:O22) -> 8662.4212 | Q23: =SUM(Q11:Q22) -> 9600 | R23: =SUM(R11:R22) -> 8558.5355 | S23: =SUM(S11:S22) -> 103.88563 | T23: =SUM(O11:O22)/(SUM(M11:M22)*$H$3) -> 0.81451613 | U23: =SUM(U11:U22) -> 1041.4645
N25: System Uncertainty | O25: =SQRT(O4^2+O5^2+O6^2+O7^2+O8^2) -> 0.042059482 | P25: % | T25: bulan kering: ±0.45–0.50
N26: Global Variability | O26: =SQRT(O3^2+O25^2) -> 0.056683331 | P26: % | T26: bulan hujan: ±0.55–0.65
N27: Variability | O27: =O28*O26 -> 491.01489 | P27: kWh | T27: Lokasi | U27: GlobHor anggaran
N28: P50 | O28: =O23 -> 8662.4212 | P28: kWh/year | T28: Kuala Lumpur | U28: ±1650–1700 kWh/m²/year
N29: P75 | O29: =O28-(0.674*O26*O28) -> 8331.4771 | P29: kWh/year | T29: Penang | U29: ±1700–1800 kWh/m²/year
N30: P90 | O30: =O28-(1.282*O26*O28) -> 8032.9401 | P30: kWh/year | T30: Johor | U30: ±1600–1700 kWh/m²/year
T31: Sabah/Sarawak | U31: boleh berbeza

Sheet PVsyst Graph Data
A1: PV SYST GRAPH DATA MASTER
A3: 1. IRRADIATION INPUT
A4: Global Horizontal Irradiation (GlobHor) | B4: =GlobHor_DiffHor!D23 -> 1674
A5: Global Incident in Collector Plane (GlobInc) | B5: =GlobHor_DiffHor!L23 -> 1615.41
A6: Effective Irradiation (GlobEff) | B6: =GlobHor_DiffHor!M23 -> 1534.6395
A8: 2. PV ENERGY LOSS DIAGRAM
A9: PV Nominal Energy at STC (kWh) | B9: =GlobHor_DiffHor!O23 -> 8662.4212
A10: Module Degradation Loss (%) | B10: 1
A11: Temperature Loss (%)
A12: Mismatch Loss (%)
A13: DC Wiring Loss (%) | B13: ='PAGE 4'!B9 -> 1.5238095
A14: Array Virtual Energy at MPP | B14: =B9*(1-8.5%) -> 7926.1154
A15: Available Energy at Inverter Output | B15: =B14*(1-0.6%) -> 7878.5587
A16: Final Energy After AC Loss | B16: =B15*(1-2.64%) -> 7670.5647
A17: Final Energy After AC Loss (kWh)
A19: 3. ENERGY BALANCE (NO BATTERY)
A20: Direct Use / E_Solar (kWh) | B20: =GlobHor_DiffHor!R23*0.2 -> 1711.7071
A21: Grid Export / E_Grid (kWh) | B21: =GlobHor_DiffHor!S23 -> 103.88563
A22: Grid Import / EFrGrid (kWh) | B22: =GlobHor_DiffHor!U23 -> 1041.4645
A24: 4. BATTERY OPTION
A25: Battery Capacity (kWh) | B25: =FORM!B80 -> 16.1
A26: Usable Energy (kWh) | B26: =FORM!B81 -> 12.1
A27: Max Charging Power (kW) | B27: =FORM!D77 -> 8.007
A28: Max Discharging Power (kW) | B28: =FORM!D79 -> TRUE
A29: Battery Stored Energy (kWh) | B29: =GlobHor_DiffHor!R23-B20 -> 6846.8284
A30: Battery Discharged Energy (kWh)
A31: Battery Loss (kWh)
A33: 5. P50 P75 P90
A34: P50 Annual Production | B34: =FORM!B13 -> 8662.4212
A35: P75
A36: P90

Sheet PAGE 1
A1: CLIENT NAME | B1: KHOR MEOW SWEE
A2: COORDINATE | B2: 5.182659 | C2: 100.48085
A3: SHORT ADDRESS | B3: 19, LORONG CENDERAWASIH INDAH 4
A5: YEAR INPUT | B5: 1800
A6: Annual Load | B6: 9600
A8: NOTES
A9: Lokasi | B9: GlobHor anggaran
A10: Selangor / Kuala Lumpur | B10: ±1650–1700 kWh/m²/year
A11: Utara | B11: ±1700–1800 kWh/m²/year
A12: Selatan | B12: ±1600–1700 kWh/m²/year
A13: Sabah/Sarawak | B13: boleh berbeza
A15: Apartment / kecil | B15: 3,000 – 5,000 kWh/year | C15: HIS MODEL
A16: Rumah biasa 1 tingkat | B16: 6,000 – 8,000 kWh/year
A17: Rumah teres besar | B17: 8,000 – 12,000 kWh/year | C17: HIT MODEL
A18: Semi-D | B18: 12,000 – 18,000 kWh/year
A19: Banglo | B19: 18,000 – 30,000 kWh/year

Sheet PAGE2
A1: PROJECT SUMMARY
A2: GEOGRAPHICAL SITE | B2: ='PAGE 1'!B3 -> 19, LORONG CENDERAWASIH INDAH 4
A3: WEARTHER DATA | B3: ='PAGE 1'!B3 -> 19, LORONG CENDERAWASIH INDAH 4
A4: LATITUDE | B4: ='PAGE 1'!B2 -> 5.182659
A5: LONGITUDE | B5: ='PAGE 1'!C2 -> 100.48085
A7: SYSTEM SUMMARY
A8: ORIENTATION #1 | C8: ORIENTATION #2 | E8: ORIENTATION #3 | H8: ORIENTATION #4
A9: TILT/AZIMUTH | B9: 20/180° | C9: TILT/AZIMUTH | D9: 20/180° | E9: TILT/AZIMUTH | F9: 20/180° | H9: TILT/AZIMUTH | I9: 20/180°
A11: System information
A12: PV Array | C12: Inverters | E12: Battery pack
A13: Nb.of modules | B13: 11 | C13: Nb.of units | D13: 1 | E13: Nb. Of units | F13: 1
A14: Pnom total | B14: =B13*'PAGE 3'!B17/1000 -> 6.93 | C14: Total power | D14: 5 | E14: Voltage | F14: 51
C15: Pnom ratio | D15: =B14/D14 -> 1.386 | E15: Capacity | F15: =F13*314 -> 314
A17: Results summary
A18: Produced Energy | B18: =GlobHor_DiffHor!O23 -> 8662.4212 | C18: Specific production | D18: =B18/PAGE2!B14 -> 1249.9886 | E18: Perf. Ratio PR | F18: =GlobHor_DiffHor!T23*100 -> 81.451613
A19: Used Energy | B19: =GlobHor_DiffHor!Q23 -> 9600 | E19: Solar Fraction SF | F19: =GlobHor_DiffHor!R23/GlobHor_DiffHor!Q23*100 -> 89.151412

Sheet PAGE 3
A1: GENERAL PARAMETERS
A2: ORIENTATION #1 | C2: ORIENTATION #2 | E2: ORIENTATION #3 | H2: ORIENTATION #4
A3: TILT/AZIMUTH | B3: =PAGE2!B9 -> 20/180° | C3: TILT/AZIMUTH | D3: =PAGE2!D9 -> 20/180° | E3: TILT/AZIMUTH | F3: =PAGE2!F9 -> 20/180° | H3: TILT/AZIMUTH | I3: =PAGE2!I9 -> 20/180°
A5: Self Consumption
A6: Jan | B6: =GlobHor_DiffHor!Q11 -> 768 | C6: Jun | D6: =GlobHor_DiffHor!Q16 -> 912 | E6: Nov. | F6: =GlobHor_DiffHor!Q21 -> 720
A7: Feb | B7: =GlobHor_DiffHor!Q12 -> 720 | C7: July | D7: =GlobHor_DiffHor!Q17 -> 864 | E7: Dec. | F7: =GlobHor_DiffHor!Q22 -> 816
A8: March | B8: =GlobHor_DiffHor!Q13 -> 768 | C8: Aug. | D8: =GlobHor_DiffHor!Q18 -> 816 | E8: Year | F8: =GlobHor_DiffHor!Q23 -> 9600
A9: April | B9: =GlobHor_DiffHor!Q14 -> 816 | C9: Sept | D9: =GlobHor_DiffHor!Q19 -> 768
A10: May | B10: =GlobHor_DiffHor!Q15 -> 864 | C10: Oct | D10: =GlobHor_DiffHor!Q20 -> 768
A12: PV Array Characteristics
A13: PV Module | C13: Inverter
A14: Manufacturer | B14: Astronergy | C14: Manufacturer | D14: Hoymiles
A15: Model | B15: CHSMM66RN(DG)/F-BH-630 | C15: Model | D15: HIS-5L-G3
A16: Custom parameters definition | B16: CHSMM66RN(DG)/F-BH-630.PAN
A17: Unit Nom. Power | B17: 630 | C17: Unit Nom. Power | D17: =PAGE2!D14 -> 5
A19: Array #1 - PV Array
A20: Orientation | B20: 1
A21: Tilt/Azimuth | B21: =B3 -> 20/180°
A22: Number of PV modules | B22: 7 | C22: Number of inverters | D22: =FORM!D31 -> 64 | E22: =FORM!E31 -> 0.64
A23: Nominal (STC) | B23: =B22*B17 -> 4410 | C23: Total power | D23: =D17*D22/100 -> 3.2
A24: Modules | B24: =B22 -> 7 | D24: HIS Model | E24: HIT Model
A25: At operating cond. (50°C) | C25: Operating voltage | D25: 90-550 | E25: 150-990
A26: Pmpp | B26: =B22*588 -> 4116 | C26: Pnom ratio | D26: =PAGE2!D15 -> 1.386 | E26: =PAGE2!D15 -> 1.386
A27: U mpp | B27: =B22*37.7 -> 263.9
A28: I mpp | B28: =IFERROR(B26/B27,0) -> 15.596817
A29: Array #2- PV Array
A30: Orientation | B30: 1
A31: Tilt/Azimuth | B31: =D3 -> 20/180°
A32: Number of PV modules | B32: 7 | C32: Number of inverters | D32: =FORM!D41 -> 64 | E32: =FORM!E41 -> 0.64
A33: Nominal (STC) | B33: =B32*B17 -> 4410 | C33: Total power | D33: =D17*D32/100 -> 3.2
A34: Modules | B34: =B32 -> 7 | D34: HIS Model | E34: HIT Model
A35: At operating cond. (50°C) | C35: Operating voltage | D35: 90-550 | E35: 150-990
A36: Pmpp | B36: =B32*588 -> 4116 | C36: Pnom ratio | D36: =PAGE2!D15 -> 1.386 | E36: =PAGE2!D15 -> 1.386
A37: U mpp | B37: =B32*37.7 -> 263.9
A38: I mpp | B38: =IFERROR(B36/B37,0) -> 15.596817
A39: Array #3- PV Array
A40: Orientation | B40: 1
A41: Tilt/Azimuth | B41: =F3 -> 20/180°
A42: Number of PV modules | B42: 7 | C42: Number of inverters | D42: =FORM!D51 -> 64 | E42: =FORM!E51 -> 0.64
A43: Nominal (STC) | B43: =B42*B17 -> 4410 | C43: Total power | D43: =D17*D42/100 -> 3.2
...

Sheet PAGE 4
A1: Grid storage - Self Consumption
A2: Battery pack | C2: Battery Input charger
A3: Nb. Of units | B3: =PAGE2!F13 -> 1 | C3: Max. charging power | D3: =B4*157/1000 -> 8.007
A4: voltage | B4: =PAGE2!F14 -> 51 | C4: Battery to Grid Inverter
A5: Nominal Capacity (C10) | B5: =PAGE2!F15 -> 314 | C5: Max. discharging power | D5: =51*314*0.5*0.95/1000 -> 7.60665
A6: Nominal energy | B6: 16.1
A8: DC wiring losses
A9: Loss Fraction | B9: =SUM(B12,D12,B16,D16)/((B12>0)+(D12>0)+(B16>0)+(D16>0)) -> 1.5238095
A10: Array #1 - PV Array (Length) | B10: 100 | C10: Array #2 - PV Array (Length) | D10: 0
A11: Global array res. | B11: =0.0175*B10/6*1000 -> 291.66667 | C11: Global array res. | D11: =0.0175*D10/6*1000 -> 0
A12: Loss fraction | B12: =16^2*B11/1000/'PAGE 3'!B23*100 -> 1.6931217 | C12: Loss fraction | D12: =16^2*D11/1000/'PAGE 3'!B43*100 -> 0
A14: Array #3 - PV Array (Length) | B14: 80 | C14: Array #4 - PV Array (Length) | D14: 0
A15: Global array res. | B15: =0.0175*B14/6*1000 -> 233.33333 | C15: Global array res. | D15: =0.0175*D14/6*1000 -> 0
A16: Loss fraction | B16: =16^2*B15/1000/'PAGE 3'!B33*100 -> 1.3544974 | C16: Loss fraction | D16: =16^2*D15/1000/'PAGE 3'!B53*100 -> 0
A18: AC wiring losses | B18: HIS Model | C18: HIT Model
A19: Inverter voltage | B19: 220 | C19: 400
A20: Global System | B20: HIS Model | C20: HIT Model
A21: Wire section | B21: 2x4 | C21: 3x3
A22: Wires length | B22: 10 | C22: 20

Sheet PAGE 5
A1: Main results
A2: System Production
A3: Produced energy | B3: =PAGE2!B18 -> 8662.4212 | C3: Specific Production | D3: =PAGE2!D18 -> 1249.9886
A4: User Energy | B4: =PAGE2!B19 -> 9600 | C4: Perf Ratio PR | D4: =PAGE2!F18 -> 81.451613
C5: Solar fraction SF | D5: =PAGE2!F19 -> 89.151412
A7: Balances and main results
B8: GlobHor | C8: DiffHor | D8: T_Amb | E8: GlobInc | F8: GlobEff | G8: Earray | H8: E_User | I8: E_Solar | J8: E_Grid | K8: EfrGrid
A9: Jan | B9: =GlobHor_DiffHor!D11 -> 144 | C9: =GlobHor_DiffHor!F11 -> 79.2 | D9: =GlobHor_DiffHor!G11 -> 27.5 | E9: =GlobHor_DiffHor!L11 -> 138.96 | F9: =GlobHor_DiffHor!M11 -> 132.012 | G9: =GlobHor_DiffHor!O11 -> 750.17139 | H9: =GlobHor_DiffHor!Q11 -> 768 | I9: =GlobHor_DiffHor!R11 -> 750.17139 | J9: =GlobHor_DiffHor!S11 -> 0 | K9: =GlobHor_DiffHor!U11 -> 17.828609
A10: Feb | B10: =GlobHor_DiffHor!D12 -> 126 | C10: =GlobHor_DiffHor!F12 -> 65.52 | D10: =GlobHor_DiffHor!G12 -> 27.8 | E10: =GlobHor_DiffHor!L12 -> 121.59 | F10: =GlobHor_DiffHor!M12 -> 115.5105 | G10: =GlobHor_DiffHor!O12 -> 648.39509 | H10: =GlobHor_DiffHor!Q12 -> 720 | I10: =GlobHor_DiffHor!R12 -> 648.39509 | J10: =GlobHor_DiffHor!S12 -> 0 | K10: =GlobHor_DiffHor!U12 -> 71.60491
A11: March | B11: =GlobHor_DiffHor!D13 -> 108 | C11: =GlobHor_DiffHor!F13 -> 51.84 | D11: =GlobHor_DiffHor!G13 -> 28.2 | E11: =GlobHor_DiffHor!L13 -> 104.22 | F11: =GlobHor_DiffHor!M13 -> 99.009 | G11: =GlobHor_DiffHor!O13 -> 535.18325 | H11: =GlobHor_DiffHor!Q13 -> 768 | I11: =GlobHor_DiffHor!R13 -> 535.18325 | J11: =GlobHor_DiffHor!S13 -> 0 | K11: =GlobHor_DiffHor!U13 -> 232.81675
A12: April | B12: =GlobHor_DiffHor!D14 -> 162 | C12: =GlobHor_DiffHor!F14 -> 81 | D12: =GlobHor_DiffHor!G14 -> 28.5 | E12: =GlobHor_DiffHor!L14 -> 156.33 | F12: =GlobHor_DiffHor!M14 -> 148.5135 | G12: =GlobHor_DiffHor!O14 -> 843.94282 | H12: =GlobHor_DiffHor!Q14 -> 816 | I12: =GlobHor_DiffHor!R14 -> 816 | J12: =GlobHor_DiffHor!S14 -> 27.942815 | K12: =GlobHor_DiffHor!U14 -> 0
A13: May | B13: =GlobHor_DiffHor!D15 -> 144 | C13: =GlobHor_DiffHor!F15 -> 76.32 | D13: =GlobHor_DiffHor!G15 -> 28.8 | E13: =GlobHor_DiffHor!L15 -> 138.96 | F13: =GlobHor_DiffHor!M15 -> 132.012 | G13: =GlobHor_DiffHor!O15 -> 759.31982 | H13: =GlobHor_DiffHor!Q15 -> 864 | I13: =GlobHor_DiffHor!R15 -> 759.31982 | J13: =GlobHor_DiffHor!S15 -> 0 | K13: =GlobHor_DiffHor!U15 -> 104.68018
A14: Jun | B14: =GlobHor_DiffHor!D16 -> 162 | C14: =GlobHor_DiffHor!F16 -> 79.38 | D14: =GlobHor_DiffHor!G16 -> 28.9 | E14: =GlobHor_DiffHor!L16 -> 156.33 | F14: =GlobHor_DiffHor!M16 -> 148.5135 | G14: =GlobHor_DiffHor!O16 -> 843.94282 | H14: =GlobHor_DiffHor!Q16 -> 912 | I14: =GlobHor_DiffHor!R16 -> 843.94282 | J14: =GlobHor_DiffHor!S16 -> 0 | K14: =GlobHor_DiffHor!U16 -> 68.057185
A15: July | B15: =GlobHor_DiffHor!D17 -> 144 | C15: =GlobHor_DiffHor!F17 -> 64.8 | D15: =GlobHor_DiffHor!G17 -> 28.7 | E15: =GlobHor_DiffHor!L17 -> 138.96 | F15: =GlobHor_DiffHor!M17 -> 132.012 | G15: =GlobHor_DiffHor!O17 -> 741.02296 | H15: =GlobHor_DiffHor!Q17 -> 864 | I15: =GlobHor_DiffHor!R17 -> 741.02296 | J15: =GlobHor_DiffHor!S17 -> 0 | K15: =GlobHor_DiffHor!U17 -> 122.97704
A16: Aug. | B16: =GlobHor_DiffHor!D18 -> 144 | C16: =GlobHor_DiffHor!F18 -> 66.24 | D16: =GlobHor_DiffHor!G18 -> 28.6 | E16: =GlobHor_DiffHor!L18 -> 138.96 | F16: =GlobHor_DiffHor!M18 -> 132.012 | G16: =GlobHor_DiffHor!O18 -> 722.7261 | H16: =GlobHor_DiffHor!Q18 -> 816 | I16: =GlobHor_DiffHor!R18 -> 722.7261 | J16: =GlobHor_DiffHor!S18 -> 0 | K16: =GlobHor_DiffHor!U18 -> 93.273904
A17: Sept | B17: =GlobHor_DiffHor!D19 -> 162 | C17: =GlobHor_DiffHor!F19 -> 81 | D17: =GlobHor_DiffHor!G19 -> 28.3 | E17: =GlobHor_DiffHor!L19 -> 156.33 | F17: =GlobHor_DiffHor!M19 -> 148.5135 | G17: =GlobHor_DiffHor!O19 -> 843.94282 | H17: =GlobHor_DiffHor!Q19 -> 768 | I17: =GlobHor_DiffHor!R19 -> 768 | J17: =GlobHor_DiffHor!S19 -> 75.942815 | K17: =GlobHor_DiffHor!U19 -> 0
A18: Oct | B18: =GlobHor_DiffHor!D20 -> 144 | C18: =GlobHor_DiffHor!F20 -> 79.2 | D18: =GlobHor_DiffHor!G20 -> 28 | E18: =GlobHor_DiffHor!L20 -> 138.96 | F18: =GlobHor_DiffHor!M20 -> 132.012 | G18: =GlobHor_DiffHor!O20 -> 759.31982 | H18: =GlobHor_DiffHor!Q20 -> 768 | I18: =GlobHor_DiffHor!R20 -> 759.31982 | J18: =GlobHor_DiffHor!S20 -> 0 | K18: =GlobHor_DiffHor!U20 -> 8.6801772
A19: Nov. | B19: =GlobHor_DiffHor!D21 -> 108 | C19: =GlobHor_DiffHor!F21 -> 66.96 | D19: =GlobHor_DiffHor!G21 -> 27.7 | E19: =GlobHor_DiffHor!L21 -> 104.22 | F19: =GlobHor_DiffHor!M21 -> 99.009 | G19: =GlobHor_DiffHor!O21 -> 542.04457 | H19: =GlobHor_DiffHor!Q21 -> 720 | I19: =GlobHor_DiffHor!R21 -> 542.04457 | J19: =GlobHor_DiffHor!S21 -> 0 | K19: =GlobHor_DiffHor!U21 -> 177.95543
A20: Dec. | B20: =GlobHor_DiffHor!D22 -> 126 | C20: =GlobHor_DiffHor!F22 -> 75.6 | D20: =GlobHor_DiffHor!G22 -> 27.5 | E20: =GlobHor_DiffHor!L22 -> 121.59 | F20: =GlobHor_DiffHor!M22 -> 115.5105 | G20: =GlobHor_DiffHor!O22 -> 672.40972 | H20: =GlobHor_DiffHor!Q22 -> 816 | I20: =GlobHor_DiffHor!R22 -> 672.40972 | J20: =GlobHor_DiffHor!S22 -> 0 | K20: =GlobHor_DiffHor!U22 -> 143.59028
A21: Year | B21: =GlobHor_DiffHor!D23 -> 1674 | C21: =GlobHor_DiffHor!F23 -> 867.06 | D21: =GlobHor_DiffHor!G23 -> 28.208333 | E21: =GlobHor_DiffHor!L23 -> 1615.41 | F21: =GlobHor_DiffHor!M23 -> 1534.6395 | G21: =GlobHor_DiffHor!O23 -> 8662.4212 | H21: =GlobHor_DiffHor!Q23 -> 9600 | I21: =GlobHor_DiffHor!R23 -> 8558.5355 | J21: =GlobHor_DiffHor!S23 -> 103.88563 | K21: =GlobHor_DiffHor!U23 -> 1041.4645

Sheet PAGE 6
A1: Loss diagram
A3: GlobHor | B3: ='PAGE 5'!B21 -> 1674
A4: Globinc | B4: =GlobHor_DiffHor!L23 -> 1615.41
A5: Pv nominal | B5: =GlobHor_DiffHor!O23 -> 8662.4212
A6: Array Virtual | B6: ='PVsyst Graph Data'!B14 -> 7926.1154
A7: Final energy after ac loss | B7: ='PVsyst Graph Data'!B16 -> 7670.5647
A8: Efr Grid | B8: =GlobHor_DiffHor!U23 -> 1041.4645
A9: Battery Stored | B9: ='PVsyst Graph Data'!B29 -> 6846.8284
A10: Direct uses | B10: =GlobHor_DiffHor!S23 -> 103.88563

Sheet PAGE 7
A1: P50=P90 evaluation | N1: NOTES
A2: Weather data | B2: 3.8 | N2: Negeri | O2: Assumption
A3: Year to year variability (Variance) | B3: 5.7 | N3: Perlis | O3: 0.035
N4: Kedah | O4: 0.035
A5: Annual production probility | N5: Pulau Pinang | O5: 0.038
A6: Variability | B6: =GlobHor_DiffHor!O27 -> 491.01489 | N6: Perak | O6: 0.038
A7: P50 | B7: =GlobHor_DiffHor!O28 -> 8662.4212 | N7: Selangor | O7: 0.039
A8: P90 | B8: =GlobHor_DiffHor!O29 -> 8331.4771 | N8: Kuala Lumpur | O8: 0.039
A9: P75 | B9: =GlobHor_DiffHor!O30 -> 8032.9401 | N9: Putrajaya | O9: 0.039
N10: Negeri Sembilan | O10: 0.04
N11: Melaka | O11: 0.04
N12: Johor | O12: 0.04
N13: Pahang | O13: 0.042
N14: Terengganu | O14: 0.043
N15: Kelantan | O15: 0.043
N16: Sabah | O16: 0.045
N17: Sarawak | O17: 0.045
